Workbook

Sheet Показатели преступности России
A1: Зависимость количества совершённых преступлений от количества безработных по регионам РФ за 2021 г.
A2: Номер | B2: Регионы | C2: Зарегистрировано преступлений в 2021 г. | D2: Количество безработных в 2021 г.
C3: Значение | D3: Значение
A4: 1 | B4: Алтайский край | C4: 39070 | D4: =U4*1000 -> 58782 | U4: 58.782 | V4: 62.646
A5: 2 | B5: Амурская область | C5: 18231 | D5: =U5*1000 -> 20354 | U5: 20.354 | V5: 23.869
A6: 3 | B6: Архангельская область | C6: 16996 | D6: =U6*1000 -> 33252 | U6: 33.252 | V6: 37.171
A7: 4 | B7: Астраханская область | C7: 13801 | D7: =U7*1000 -> 38582 | U7: 38.582 | V7: 39.248
A8: 5 | B8: Белгородская область | C8: 14067 | D8: =U8*1000 -> 34974 | U8: 34.974 | V8: 40.888
A9: 6 | B9: Брянская область | C9: 14202 | D9: =U9*1000 -> 20080 | U9: 20.08 | V9: 23.204
A10: 7 | B10: Владимирская область | C10: 16248 | D10: =U10*1000 -> 27999 | U10: 27.999 | V10: 40.149
A11: 8 | B11: Волгоградская область | C11: 37910 | D11: =U11*1000 -> 64148 | U11: 64.148 | V11: 97.216
A12: 9 | B12: Вологодская область | C12: 17775 | D12: =U12*1000 -> 25905 | U12: 25.905 | V12: 35.101
A13: 10 | B13: Воронежская область | C13: 29552 | D13: =U13*1000 -> 45599 | U13: 45.599 | V13: 50.659
A14: 11 | B14: Еврейская АО | C14: 3323 | D14: =U14*1000 -> 4189 | U14: 4.189 | V14: 4.791
A15: 12 | B15: Забайкальский край | C15: 21707 | D15: =U15*1000 -> 47321 | U15: 47.321 | V15: 50.473
... A88: 85 | B88: г. Севастополь | C88: 6136 | D88: =U88*1000 -> 73230 | U88: 73.23 | V88: 94.954
B91: Источник | C91: http://crimestat.ru/offenses_table

Sheet Анализ данных
A1: ВЫВОД ИТОГОВ
A3: Регрессионная статистика
A4: Множественный R | B4: 0.71879981
A5: R-квадрат | B5: 0.51667317
A6: Нормированный R-квадрат | B6: 0.51047667
A7: Стандартная ошибка | B7: 10625.891
A8: Наблюдения | B8: 80
A10: Дисперсионный анализ
B11: df | C11: SS | D11: MS | E11: F | F11: Значимость F
A12: Регрессия | B12: 1 | C12: 9.4145668e+09 | D12: 9.4145668e+09 | E12: 83.381481 | F12: 6.0027001e-14
A13: Остаток | B13: 78 | C13: 8.8069461e+09 | D13: 1.1290957e+08
A14: Итого | B14: 79 | C14: 1.8221513e+10
B16: Коэффициенты | C16: Стандартная ошибка | D16: t-статистика | E16: P-Значение | F16: Нижние 95% | G16: Верхние 95% | H16: Нижние 95,0% | I16: Верхние 95,0%
A17: Y-пересечение | B17: 3030.6156 | C17: 2187.1928 | D17: 1.3856189 | E17: 0.16981262 | F17: -1323.7507 | G17: 7384.9819 | H17: -1323.7507 | I17: 7384.9819
A18: Переменная X 1 | B18: 0.45483525 | C18: 0.049810318 | D18: 9.1313461 | E18: 6.0027001e-14 | F18: 0.35567053 | G18: 0.55399998 | H18: 0.35567053 | I18: 0.55399998
A22: ВЫВОД ОСТАТКА
A24: Наблюдение | B24: Предсказанное Y | C24: Остатки | D24: X | E24: Y точное | F24: Предсказанное Y | G24: Y-Yx | H24: |Y-Yx| | I24: (Y-Yx)^2
A25: 1 | B25: 29766.741 | C25: 9303.2585 | D25: ='2021 г.'!T3 -> 58782 | E25: ='2021 г.'!U3 -> 39070 | F25: 29766.741 | G25: =E25-F25 -> 9303.2585 | H25: =ABS(G25) -> 9303.2585 | I25: =H25^2 -> 86550619
A26: 2 | B26: 12288.332 | C26: 5942.6676 | D26: ='2021 г.'!T4 -> 20354 | E26: ='2021 г.'!U4 -> 18231 | F26: 12288.332 | G26: =E26-F26 -> 5942.6676 | H26: =ABS(G26) -> 5942.6676 | I26: =H26^2 -> 35315299
A27: 3 | B27: 18154.797 | C27: -1158.7975 | D27: ='2021 г.'!T5 -> 33252 | E27: ='2021 г.'!U5 -> 16996 | F27: 18154.797 | G27: =E27-F27 -> -1158.7975 | H27: =ABS(G27) -> 1158.7975 | I27: =H27^2 -> 1342811.5
A28: 4 | B28: 20579.069 | C28: -6778.0694 | D28: ='2021 г.'!T6 -> 38582 | E28: ='2021 г.'!U6 -> 13801 | F28: 20579.069 | G28: =E28-F28 -> -6778.0694 | H28: =ABS(G28) -> 6778.0694 | I28: =H28^2 -> 45942224
A29: 5 | B29: 18938.024 | C29: -4871.0238 | D29: ='2021 г.'!T7 -> 34974 | E29: ='2021 г.'!U7 -> 14067 | F29: 18938.024 | G29: =E29-F29 -> -4871.0238 | H29: =ABS(G29) -> 4871.0238 | I29: =H29^2 -> 23726873
A30: 6 | B30: 12163.707 | C30: 2038.2925 | D30: ='2021 г.'!T8 -> 20080 | E30: ='2021 г.'!U8 -> 14202 | F30: 12163.707 | G30: =E30-F30 -> 2038.2925 | H30: =ABS(G30) -> 2038.2925 | I30: =H30^2 -> 4154636.3
A31: 7 | B31: 15765.548 | C31: 482.45213 | D31: ='2021 г.'!T9 -> 27999 | E31: ='2021 г.'!U9 -> 16248 | F31: 15765.548 | G31: =E31-F31 -> 482.45213 | H31: =ABS(G31) -> 482.45213 | I31: =H31^2 -> 232760.06
A32: 8 | B32: 32207.387 | C32: 5702.6125 | D32: ='2021 г.'!T10 -> 64148 | E32: ='2021 г.'!U10 -> 37910 | F32: 32207.387 | G32: =E32-F32 -> 5702.6125 | H32: =ABS(G32) -> 5702.6125 | I32: =H32^2 -> 32519790
A33: 9 | B33: 14813.123 | C33: 2961.8771 | D33: ='2021 г.'!T11 -> 25905 | E33: ='2021 г.'!U11 -> 17775 | F33: 14813.123 | G33: =E33-F33 -> 2961.8771 | H33: =ABS(G33) -> 2961.8771 | I33: =H33^2 -> 8772716.3
A34: 10 | B34: 23770.648 | C34: 5781.3517 | D34: ='2021 г.'!T12 -> 45599 | E34: ='2021 г.'!U12 -> 29552 | F34: 23770.648 | G34: =E34-F34 -> 5781.3517 | H34: =ABS(G34) -> 5781.3517 | I34: =H34^2 -> 33424027
A35: 11 | B35: 4935.9205 | C35: -1612.9205 | D35: ='2021 г.'!T13 -> 4189 | E35: ='2021 г.'!U13 -> 3323 | F35: 4935.9205 | G35: =E35-F35 -> -1612.9205 | H35: =ABS(G35) -> 1612.9205 | I35: =H35^2 -> 2601512.5
A36: 12 | B36: 24553.875 | C36: -2846.8746 | D36: ='2021 г.'!T14 -> 47321 | E36: ='2021 г.'!U14 -> 21707 | F36: 24553.875 | G36: =E36-F36 -> -2846.8746 | H36: =ABS(G36) -> 2846.8746 | I36: =H36^2 -> 8104695.2
... A104: 80 | B104: 36338.201 | C104: -30202.201 | D104: ='2021 г.'!T82 -> 73230 | E104: ='2021 г.'!U82 -> 6136 | F104: 36338.201 | G104: =E104-F104 -> -30202.201 | H104: =ABS(G104) -> 30202.201 | I104: =H104^2 -> 9.1217296e+08
D105: ='2021 г.'!T83 -> 36868.287 | I105: =AVERAGE(I25:I104) -> 1.1008683e+08
D106: ='2021 г.'!T84 -> 0 | I106: =SQRT(I105) -> 10492.227

Sheet Лист1
A1: ВЫВОД ИТОГОВ
A3: Регрессионная статистика
A4: Множественный R | B4: 0.74283968
A5: R-квадрат | B5: 0.55181079
A6: Нормированный R-квадрат | B6: 0.54606477
A7: Стандартная ошибка | B7: 0.61027074
A8: Наблюдения | B8: 80
A10: Дисперсионный анализ
B11: df | C11: SS | D11: MS | E11: F | F11: Значимость F
A12: Регрессия | B12: 1 | C12: 35.765844 | D12: 35.765844 | E12: 96.03364 | F12: 3.0640431e-15
A13: Остаток | B13: 78 | C13: 29.049569 | D13: 0.37243037
A14: Итого | B14: 79 | C14: 64.815413
B16: Коэффициенты | C16: Стандартная ошибка | D16: t-статистика | E16: P-Значение | F16: Нижние 95% | G16: Верхние 95% | H16: Нижние 95,0% | I16: Верхние 95,0%
A17: Y-пересечение | B17: 1.6165556 | C17: 0.81397598 | D17: 1.9859991 | E17: 0.050546841 | F17: -0.0039461285 | G17: 3.2370572 | H17: -0.0039461285 | I17: 3.2370572
A18: Переменная X 1 | B18: 0.77591326 | C18: 0.079177445 | D18: 9.7996755 | E18: 3.0640431e-15 | F18: 0.61828308 | G18: 0.93354345 | H18: 0.61828308 | I18: 0.93354345
A22: ВЫВОД ОСТАТКА
A24: Наблюдение | B24: Предсказанное Y | C24: Остатки | E24: X | F24: Y точное | G24: Y предсказанное | H24: Y-Yx | I24: |Y-Yx| | J24: (Y-Yx)^2
A25: 1 | B25: 10.137318 | C25: 0.43579254 | E25: ='2021 г.'!AR3 -> 10.981591 | F25: ='2021 г.'!AS3 -> 10.57311 | G25: =B25 -> 10.137318 | H25: =F25-G25 -> 0.43579254 | I25: =ABS(H25) -> 0.43579254 | J25: =I25^2 -> 0.18991513
A26: 2 | B26: 9.3144165 | C26: 0.49646227 | E26: ='2021 г.'!AR4 -> 9.9210327 | F26: ='2021 г.'!AS4 -> 9.8108787 | G26: =B26 -> 9.3144165 | H26: =F26-G26 -> 0.49646227 | I26: =ABS(H26) -> 0.49646227 | J26: =I26^2 -> 0.24647478
A27: 3 | B27: 9.6952638 | C27: 0.045469551 | E27: ='2021 г.'!AR5 -> 10.41187 | F27: ='2021 г.'!AS5 -> 9.7407333 | G27: =B27 -> 9.6952638 | H27: =F27-G27 -> 0.045469551 | I27: =ABS(H27) -> 0.045469551 | J27: =I27^2 -> 0.0020674801
A28: 4 | B28: 9.8106195 | C28: -0.27812317 | E28: ='2021 г.'!AR6 -> 10.560541 | F28: ='2021 г.'!AS6 -> 9.5324963 | G28: =B28 -> 9.8106195 | H28: =F28-G28 -> -0.27812317 | I28: =ABS(H28) -> 0.27812317 | J28: =I28^2 -> 0.077352495
A29: 5 | B29: 9.7344396 | C29: -0.18285271 | E29: ='2021 г.'!AR7 -> 10.46236 | F29: ='2021 г.'!AS7 -> 9.5515869 | G29: =B29 -> 9.7344396 | H29: =F29-G29 -> -0.18285271 | I29: =ABS(H29) -> 0.18285271 | J29: =I29^2 -> 0.033435115
A30: 6 | B30: 9.3039004 | C30: 0.2572377 | E30: ='2021 г.'!AR8 -> 9.9074796 | F30: ='2021 г.'!AS8 -> 9.5611381 | G30: =B30 -> 9.3039004 | H30: =F30-G30 -> 0.2572377 | I30: =ABS(H30) -> 0.2572377 | J30: =I30^2 -> 0.066171235
A31: 7 | B31: 9.5618485 | C31: 0.13387663 | E31: ='2021 г.'!AR9 -> 10.239924 | F31: ='2021 г.'!AS9 -> 9.6957251 | G31: =B31 -> 9.5618485 | H31: =F31-G31 -> 0.13387663 | I31: =ABS(H31) -> 0.13387663 | J31: =I31^2 -> 0.017922952
A32: 8 | B32: 10.205099 | C32: 0.33787092 | E32: ='2021 г.'!AR10 -> 11.068948 | F32: ='2021 г.'!AS10 -> 10.54297 | G32: =B32 -> 10.205099 | H32: =F32-G32 -> 0.33787092 | I32: =ABS(H32) -> 0.33787092 | J32: =I32^2 -> 0.11415676
A33: 9 | B33: 9.5015346 | C33: 0.28401369 | E33: ='2021 г.'!AR11 -> 10.162191 | F33: ='2021 г.'!AS11 -> 9.7855483 | G33: =B33 -> 9.5015346 | H33: =F33-G33 -> 0.28401369 | I33: =ABS(H33) -> 0.28401369 | J33: =I33^2 -> 0.080663774
A34: 10 | B34: 9.9402746 | C34: 0.35363215 | E34: ='2021 г.'!AR12 -> 10.727641 | F34: ='2021 г.'!AS12 -> 10.293907 | G34: =B34 -> 9.9402746 | H34: =F34-G34 -> 0.35363215 | I34: =ABS(H34) -> 0.35363215 | J34: =I34^2 -> 0.12505569
A35: 11 | B35: 8.0878408 | C35: 0.020782462 | E35: ='2021 г.'!AR13 -> 8.3402173 | F35: ='2021 г.'!AS13 -> 8.1086233 | G35: =B35 -> 8.0878408 | H35: =F35-G35 -> 0.020782462 | I35: =ABS(H35) -> 0.020782462 | J35: =I35^2 -> 0.00043191073
A36: 12 | B36: 9.9690364 | C36: 0.016353659 | E36: ='2021 г.'!AR14 -> 10.764709 | F36: ='2021 г.'!AS14 -> 9.9853901 | G36: =B36 -> 9.9690364 | H36: =F36-G36 -> 0.016353659 | I36: =ABS(H36) -> 0.016353659 | J36: =I36^2 -> 0.00026744217
... A104: 80 | B104: 10.30784 | C104: -1.5859114 | E104: ='2021 г.'!AR82 -> 11.20136 | F104: ='2021 г.'!AS82 -> 8.7219283 | G104: =B104 -> 10.30784 | H104: =F104-G104 -> -1.5859114 | I104: =ABS(H104) -> 1.5859114 | J104: =I104^2 -> 2.5151149
J105: =AVERAGE(J25:J104) -> 0.36311961
J106: =SQRT(J105) -> 0.60259407

Sheet 2021 г.
A1: Номер | B1: Регионы | C1: Зарегистрировано преступлений в 2021 г.(Y) | D1: Количество безработных в 2021 г. (X) | O1: Номер | P1: Регионы | Q1: Зарегистрировано преступлений в 2021 г.(Y) | R1: Количество безработных в 2021 г. (X)
C2: Значение | D2: Значение | Q2: Значение | R2: Значение | T2: X | U2: Y | V2: X*Y | W2: (Х-Хср)^2 | X2: x^2 | Y2: Y^2 | AA2: Sx = | AB2: =SQRT(X83-T83^2) -> 23850.696 | AR2: ln(X) | AS2: ln(Y) | AT2: * | AU2: (ln(Х)-ln(Х)ср)^2 | AV2: x^2 | AW2: Y^2 | AY2: Xср = | AZ2: =AR83 -> 10.244222
A3: 1 | B3: Алтайский край | C3: 39070 | D3: ='Показатели преступности России'!U4*1000 -> 58782 | O3: 1 | P3: Алтайский край | Q3: 39070 | R3: ='Показатели преступности России'!D4 -> 58782 | T3: =R3 -> 58782 | U3: =Q3 -> 39070 | V3: =T3*U3 -> 2296612740 | W3: =(T3-T$83)^2 -> 4.802108e+08 | X3: =T3^2 -> 3455323524 | Y3: =U3^2 -> 1526464900 | AA3: Sy = | AB3: =SQRT(Y83-U83^2) -> 15092.015 | AH3: Xср = | AI3: =T83 -> 36868.287 | AR3: =LN(T3) -> 10.981591 | AS3: =LN(U3) -> 10.57311 | AT3: =AR3*AS3 -> 116.10957 | AU3: =(AR3-AR$83)^2 -> 0.54371372 | AV3: =AR3^2 -> 120.59534 | AW3: =AS3^2 -> 111.79066 | AY3: Yср = | AZ3: =AS83 -> 9.5651829
A4: 2 | B4: Амурская область | C4: 18231 | D4: ='Показатели преступности России'!U5*1000 -> 20354 | O4: 2 | P4: Амурская область | Q4: 18231 | R4: ='Показатели преступности России'!D5 -> 20354 | T4: =R4 -> 20354 | U4: =Q4 -> 18231 | V4: =T4*U4 -> 371073774 | W4: =(T4-T$83)^2 -> 2.7272169e+08 | X4: =T4^2 -> 414285316 | Y4: =U4^2 -> 332369361 | AH4: Yср = | AI4: =U83 -> 19799.612 | AR4: =LN(T4) -> 9.9210327 | AS4: =LN(U4) -> 9.8108787 | AT4: =AR4*AS4 -> 97.334049 | AU4: =(AR4-AR$83)^2 -> 0.10445098 | AV4: =AR4^2 -> 98.42689 | AW4: =AS4^2 -> 96.253341 | AY4: X*Yср = | AZ4: =AT83 -> 98.564042
A5: 3 | B5: Архангельская область | C5: 16996 | D5: ='Показатели преступности России'!U6*1000 -> 33252 | O5: 3 | P5: Архангельская область | Q5: 16996 | R5: ='Показатели преступности России'!D6 -> 33252 | T5: =R5 -> 33252 | U5: =Q5 -> 16996 | V5: =T5*U5 -> 565150992 | W5: =(T5-T$83)^2 -> 13077535 | X5: =T5^2 -> 1105695504 | Y5: =U5^2 -> 288864016 | AA5: Коэф. корреляции по формуле: | AC5: =(V83-U83*T83)/(AB2*AB3) -> 0.71879981 | AH5: X*Yср = | AI5: =V83 -> 9.8871344e+08 | AR5: =LN(T5) -> 10.41187 | AS5: =LN(U5) -> 9.7407333 | AT5: =AR5*AS5 -> 101.41925 | AU5: =(AR5-AR$83)^2 -> 0.028106083 | AV5: =AR5^2 -> 108.40704 | AW5: =AS5^2 -> 94.881885 | AY5: S^2(x) = | AZ5: =AV83 -> 105.68667
A6: 4 | B6: Астраханская область | C6: 13801 | D6: ='Показатели преступности России'!U7*1000 -> 38582 | O6: 4 | P6: Астраханская область | Q6: 13801 | R6: ='Показатели преступности России'!D7 -> 38582 | T6: =R6 -> 38582 | U6: =Q6 -> 13801 | V6: =T6*U6 -> 532470182 | W6: =(T6-T$83)^2 -> 2936810.5 | X6: =T6^2 -> 1488570724 | Y6: =U6^2 -> 190467601 | AA6: Коэф. корелляции с пом. "КОРРЕЛ": | AC6: =CORREL(T3:T82,U3:U82) -> 0.71879981 | AH6: S^2(x) = | AI6: =W83 -> 5.6885571e+08 | AR6: =LN(T6) -> 10.560541 | AS6: =LN(U6) -> 9.5324963 | AT6: =AR6*AS6 -> 100.66832 | AU6: =(AR6-AR$83)^2 -> 0.1000581 | AV6: =AR6^2 -> 111.52503 | AW6: =AS6^2 -> 90.868486
A7: 5 | B7: Белгородская область | C7: 14067 | D7: ='Показатели преступности России'!U8*1000 -> 34974 | O7: 5 | P7: Белгородская область | Q7: 14067 | R7: ='Показатели преступности России'!D8 -> 34974 | T7: =R7 -> 34974 | U7: =Q7 -> 14067 | V7: =T7*U7 -> 491979258 | W7: =(T7-T$83)^2 -> 3588325.1 | X7: =T7^2 -> 1223180676 | Y7: =U7^2 -> 197880489 | AR7: =LN(T7) -> 10.46236 | AS7: =LN(U7) -> 9.5515869 | AT7: =AR7*AS7 -> 99.932143 | AU7: =(AR7-AR$83)^2 -> 0.047584493 | AV7: =AR7^2 -> 109.46098 | AW7: =AS7^2 -> 91.232812 | AY7: b1 = | AZ7: =(AZ4-AZ3*AZ2)/AZ5 -> 0.0054518651
A8: 6 | B8: Брянская область | C8: 14202 | D8: ='Показатели преступности России'!U9*1000 -> 20080 | O8: 6 | P8: Брянская область | Q8: 14202 | R8: ='Показатели преступности России'!D9 -> 20080 | T8: =R8 -> 20080 | U8: =Q8 -> 14202 | V8: =T8*U8 -> 285176160 | W8: =(T8-T$83)^2 -> 2.818466e+08 | X8: =T8^2 -> 403206400 | Y8: =U8^2 -> 201696804 | AH8: b1 = | AI8: =(AI5-AI4*AI3)/AI6 -> 0.45483525 | AR8: =LN(T8) -> 9.9074796 | AS8: =LN(U8) -> 9.5611381 | AT8: =AR8*AS8 -> 94.72678 | AU8: =(AR8-AR$83)^2 -> 0.11339513 | AV8: =AR8^2 -> 98.158152 | AW8: =AS8^2 -> 91.415361 | AY8: b0 = | AZ8: =AZ3-AZ7*AZ2 -> 9.5093328
A9: 7 | B9: Владимирская область | C9: 16248 | D9: ='Показатели преступности России'!U10*1000 -> 27999 | O9: 7 | P9: Владимирская область | Q9: 16248 | R9: ='Показатели преступности России'!D10 -> 27999 | T9: =R9 -> 27999 | U9: =Q9 -> 16248 | V9: =T9*U9 -> 454927752 | W9: =(T9-T$83)^2 -> 78664261 | X9: =T9^2 -> 783944001 | Y9: =U9^2 -> 263997504 | AH9: b0 = | AI9: =AI4-AI8*AI3 -> 3030.6156 | AR9: =LN(T9) -> 10.239924 | AS9: =LN(U9) -> 9.6957251 | AT9: =AR9*AS9 -> 99.283489 | AU9: =(AR9-AR$83)^2 -> 1.8467915e-05 | AV9: =AR9^2 -> 104.85605 | AW9: =AS9^2 -> 94.007085
A10: 8 | B10: Волгоградская область | C10: 37910 | D10: ='Показатели преступности России'!U11*1000 -> 64148 | O10: 8 | P10: Волгоградская область | Q10: 37910 | R10: ='Показатели преступности России'!D11 -> 64148 | T10: =R10 -> 64148 | U10: =Q10 -> 37910 | V10: =T10*U10 -> 2.4318507e+09 | W10: =(T10-T$83)^2 -> 7.4418271e+08 | X10: =T10^2 -> 4.1149659e+09 | Y10: =U10^2 -> 1437168100 | AH10: Уравнение регрессии | AK10: Коэффициент b1 = 0,45, он характеризует, как значение параметра Y будет изменяться при изменении параметра X, в данном случае количесвто преступлений будет увеличиваться на 2 при увеличении количества безработных граждан на 4. Коэффициент b2 = 3030,62, и так как в нашей выборке нет значения X = 0, b2 не имеет никакой интерпретации. Средняя квадратическая ошибка получилась довольно большой, это показывает, что модель далеко не лучшая. Результаты выполнения "вручную" и с помощью "Анализа данных" совпадают, значит мы сделали всё правильно. | AR10: =LN(T10) -> 11.068948 | AS10: =LN(U10) -> 10.54297 | AT10: =AR10*AS10 -> 116.69959 | AU10: =(AR10-AR$83)^2 -> 0.68017411 | AV10: =AR10^2 -> 122.52161 | AW10: =AS10^2 -> 111.15422
A11: 9 | B11: Вологодская область | C11: 17775 | D11: ='Показатели преступности России'!U12*1000 -> 25905 | O11: 9 | P11: Вологодская область | Q11: 17775 | R11: ='Показатели преступности России'!D12 -> 25905 | T11: =R11 -> 25905 | U11: =Q11 -> 17775 | V11: =T11*U11 -> 460461375 | W11: =(T11-T$83)^2 -> 1.2019367e+08 | X11: =T11^2 -> 671069025 | Y11: =U11^2 -> 315950625 | AR11: =LN(T11) -> 10.162191 | AS11: =LN(U11) -> 9.7855483 | AT11: =AR11*AS11 -> 99.442613 | AU11: =(AR11-AR$83)^2 -> 0.006728958 | AV11: =AR11^2 -> 103.27013 | AW11: =AS11^2 -> 95.756955
A12: 10 | B12: Воронежская область | C12: 29552 | D12: ='Показатели преступности России'!U13*1000 -> 45599 | O12: 10 | P12: Воронежская область | Q12: 29552 | R12: ='Показатели преступности России'!D13 -> 45599 | T12: =R12 -> 45599 | U12: =Q12 -> 29552 | V12: =T12*U12 -> 1347541648 | W12: =(T12-T$83)^2 -> 76225341 | X12: =T12^2 -> 2079268801 | Y12: =U12^2 -> 873320704 | AR12: =LN(T12) -> 10.727641 | AS12: =LN(U12) -> 10.293907 | AT12: =AR12*AS12 -> 110.42934 | AU12: =(AR12-AR$83)^2 -> 0.23369447 | AV12: =AR12^2 -> 115.08228 | AW12: =AS12^2 -> 105.96452
A13: 11 | B13: Еврейская АО | C13: 3323 | D13: ='Показатели преступности России'!U14*1000 -> 4189 | O13: 11 | P13: Еврейская АО | Q13: 3323 | R13: ='Показатели преступности России'!D14 -> 4189 | T13: =R13 -> 4189 | U13: =Q13 -> 3323 | V13: =T13*U13 -> 13920047 | W13: =(T13-T$83)^2 -> 1.0679358e+09 | X13: =T13^2 -> 17547721 | Y13: =U13^2 -> 11042329 | AR13: =LN(T13) -> 8.3402173 | AS13: =LN(U13) -> 8.1086233 | AT13: =AR13*AS13 -> 67.62768 | AU13: =(AR13-AR$83)^2 -> 3.6252319 | AV13: =AR13^2 -> 69.559225 | AW13: =AS13^2 -> 65.749771
A14: 12 | B14: Забайкальский край | C14: 21707 | D14: ='Показатели преступности России'!U15*1000 -> 47321 | O14: 12 | P14: Забайкальский край | Q14: 21707 | R14: ='Показатели преступности России'!D15 -> 47321 | T14: =R14 -> 47321 | U14: =Q14 -> 21707 | V14: =T14*U14 -> 1027196947 | W14: =(T14-T$83)^2 -> 1.092592e+08 | X14: =T14^2 -> 2239277041 | Y14: =U14^2 -> 471193849 | AR14: =LN(T14) -> 10.764709 | AS14: =LN(U14) -> 9.9853901 | AT14: =AR14*AS14 -> 107.48982 | AU14: =(AR14-AR$83)^2 -> 0.2709077 | AV14: =AR14^2 -> 115.87897 | AW14: =AS14^2 -> 99.708015
A15: 13 | B15: Ивановская область | C15: 12064 | D15: ='Показатели преступности России'!U16*1000 -> 22510 | O15: 13 | P15: Ивановская область | Q15: 12064 | R15: ='Показатели преступности России'!D16 -> 22510 | T15: =R15 -> 22510 | U15: =Q15 -> 12064 | V15: =T15*U15 -> 271560640 | W15: =(T15-T$83)^2 -> 2.0616042e+08 | X15: =T15^2 -> 506700100 | Y15: =U15^2 -> 145540096 | AR15: =LN(T15) -> 10.021715 | AS15: =LN(U15) -> 9.3979811 | AT15: =AR15*AS15 -> 94.183887 | AU15: =(AR15-AR$83)^2 -> 0.049509174 | AV15: =AR15^2 -> 100.43477 | AW15: =AS15^2 -> 88.322049
A16: 14 | B16: Иркутская область | C16: 39363 | D16: ='Показатели преступности России'!U17*1000 -> 68776 | F16: Удалили выбросы по X и по Y. | O16: 14 | P16: Иркутская область | Q16: 39363 | R16: ='Показатели преступности России'!D17 -> 68776 | T16: =R16 -> 68776 | U16: =Q16 -> 39363 | V16: =T16*U16 -> 2707229688 | W16: =(T16-T$83)^2 -> 1.0181021e+09 | X16: =T16^2 -> 4730138176 | Y16: =U16^2 -> 1549445769 | AR16: =LN(T16) -> 11.13861 | AS16: =LN(U16) -> 10.580582 | AT16: =AR16*AS16 -> 117.85297 | AU16: =(AR16-AR$83)^2 -> 0.799931 | AV16: =AR16^2 -> 124.06864 | AW16: =AS16^2 -> 111.94871
A17: 15 | B17: Кабардино-Балкарская Респ. | C17: 7557 | D17: ='Показатели преступности России'!U18*1000 -> 54876 | O17: 15 | P17: Кабардино-Балкарская Респ. | Q17: 7557 | R17: ='Показатели преступности России'!D18 -> 54876 | T17: =R17 -> 54876 | U17: =Q17 -> 7557 | V17: =T17*U17 -> 414697932 | W17: =(T17-T$83)^2 -> 3.2427771e+08 | X17: =T17^2 -> 3011375376 | Y17: =U17^2 -> 57108249 | AR17: =LN(T17) -> 10.912831 | AS17: =LN(U17) -> 8.9302296 | AT17: =AR17*AS17 -> 97.454089 | AU17: =(AR17-AR$83)^2 -> 0.44703916 | AV17: =AR17^2 -> 119.08989 | AW17: =AS17^2 -> 79.749
A18: 16 | B18: Калининградская область | C18: 13269 | D18: ='Показатели преступности России'!U19*1000 -> 27105 | O18: 16 | P18: Калининградская область | Q18: 13269 | R18: ='Показатели преступности России'!D19 -> 27105 | T18: =R18 -> 27105 | U18: =Q18 -> 13269 | V18: =T18*U18 -> 359656245 | W18: =(T18-T$83)^2 -> 95321783 | X18: =T18^2 -> 734681025 | Y18: =U18^2 -> 176066361 | AR18: =LN(T18) -> 10.207473 | AS18: =LN(U18) -> 9.4931858 | AT18: =AR18*AS18 -> 96.901442 | AU18: =(AR18-AR$83)^2 -> 0.0013504165 | AV18: =AR18^2 -> 104.19252 | AW18: =AS18^2 -> 90.120576
A19: 17 | B19: Калужская область | C19: 15961 | D19: ='Показатели преступности России'!U20*1000 -> 22592 | O19: 17 | P19: Калужская область | Q19: 15961 | R19: ='Показатели преступности России'!D20 -> 22592 | T19: =R19 -> 22592 | U19: =Q19 -> 15961 | V19: =T19*U19 -> 360590912 | W19: =(T19-T$83)^2 -> 2.0381238e+08 | X19: =T19^2 -> 510398464 | Y19: =U19^2 -> 254753521 | AR19: =LN(T19) -> 10.025351 | AS19: =LN(U19) -> 9.6779035 | AT19: =AR19*AS19 -> 97.024381 | AU19: =(AR19-AR$83)^2 -> 0.047904237 | AV19: =AR19^2 -> 100.50767 | AW19: =AS19^2 -> 93.661817
A20: 18 | B20: Камчатский край | C20: 5909 | D20: ='Показатели преступности России'!U21*1000 -> 5840 | O20: 18 | P20: Камчатский край | Q20: 5909 | R20: ='Показатели преступности России'!D21 -> 5840 | T20: =R20 -> 5840 | U20: =Q20 -> 5909 | V20: =T20*U20 -> 34508560 | W20: =(T20-T$83)^2 -> 9.6275463e+08 | X20: =T20^2 -> 34105600 | Y20: =U20^2 -> 34916281 | AR20: =LN(T20) -> 8.6724861 | AS20: =LN(U20) -> 8.6842319 | AT20: =AR20*AS20 -> 75.31388 | AU20: =(AR20-AR$83)^2 -> 2.4703523 | AV20: =AR20^2 -> 75.212015 | AW20: =AS20^2 -> 75.415884
A21: 19 | B21: Карачаево-Черкесская Респ. | C21: 4345 | D21: ='Показатели преступности России'!U22*1000 -> 26425 | O21: 19 | P21: Карачаево-Черкесская Респ. | Q21: 4345 | R21: ='Показатели преступности России'!D22 -> 26425 | T21: =R21 -> 26425 | U21: =Q21 -> 4345 | V21: =T21*U21 -> 114816625 | W21: =(T21-T$83)^2 -> 1.0906225e+08 | X21: =T21^2 -> 698280625 | Y21: =U21^2 -> 18879025 | AR21: =LN(T21) -> 10.182066 | AS21: =LN(U21) -> 8.376781 | AT21: =AR21*AS21 -> 85.292936 | AU21: =(AR21-AR$83)^2 -> 0.0038633304 | AV21: =AR21^2 -> 103.67446 | AW21: =AS21^2 -> 70.170461
A22: 20 | B22: Кемеровская область-Кузбасс | C22: 50465 | D22: ='Показатели преступности России'!U23*1000 -> 68552 | O22: 20 | P22: Кемеровская область-Кузбасс | Q22: 50465 | R22: ='Показатели преступности России'!D23 -> 68552 | T22: =R22 -> 68552 | U22: =Q22 -> 50465 | V22: =T22*U22 -> 3459476680 | W22: =(T22-T$83)^2 -> 1.0038576e+09 | X22: =T22^2 -> 4699376704 | Y22: =U22^2 -> 2546716225 | AR22: =LN(T22) -> 11.135348 | AS22: =LN(U22) -> 10.829035 | AT22: =AR22*AS22 -> 120.58508 | AU22: =(AR22-AR$83)^2 -> 0.79410618 | AV22: =AR22^2 -> 123.99597 | AW22: =AS22^2 -> 117.26801
A23: 21 | B23: Кировская область | C23: 19034 | D23: ='Показатели преступности России'!U24*1000 -> 29046 | O23: 21 | P23: Кировская область | Q23: 19034 | R23: ='Показатели преступности России'!D24 -> 29046 | T23: =R23 -> 29046 | U23: =Q23 -> 19034 | V23: =T23*U23 -> 552861564 | W23: =(T23-T$83)^2 -> 61188182 | X23: =T23^2 -> 843670116 | Y23: =U23^2 -> 362293156 | AR23: =LN(T23) -> 10.276636 | AS23: =LN(U23) -> 9.8539821 | AT23: =AR23*AS23 -> 101.26579 | AU23: =(AR23-AR$83)^2 -> 0.0010507033 | AV23: =AR23^2 -> 105.60925 | AW23: =AS23^2 -> 97.100964
A24: 22 | B24: Костромская область | C24: 8927 | D24: ='Показатели преступности России'!U25*1000 -> 12404 | O24: 22 | P24: Костромская область | Q24: 8927 | R24: ='Показатели преступности России'!D25 -> 12404 | T24: =R24 -> 12404 | U24: =Q24 -> 8927 | V24: =T24*U24 -> 110730508 | W24: =(T24-T$83)^2 -> 5.9850136e+08 | X24: =T24^2 -> 153859216 | Y24: =U24^2 -> 79691329 | AA24: Значение коэффициента корреляции, расчитанное двумя способами примерно совпадает. Между показателями присутсвует средняя прямая зависомость, так как значение 0,72 соответсвует средней корреляции и по графику мы можем отметить, что корреляция положительная линейная. | AR24: =LN(T24) -> 9.4257743 | AS24: =LN(U24) -> 9.0968357 | AT24: =AR24*AS24 -> 85.74472 | AU24: =(AR24-AR$83)^2 -> 0.66985586 | AV24: =AR24^2 -> 88.845221 | AW24: =AS24^2 -> 82.752419
A25: 23 | B25: Краснодарский край | C25: 78183 | D25: ='Показатели преступности России'!U26*1000 -> 145782 | O25: 23 | P25: Красноярский край | Q25: 47027 | R25: ='Показатели преступности России'!D27 -> 51356 | T25: =R25 -> 51356 | U25: =Q25 -> 47027 | V25: =T25*U25 -> 2415118612 | W25: =(T25-T$83)^2 -> 2.0989381e+08 | X25: =T25^2 -> 2637438736 | Y25: =U25^2 -> 2211538729 | AR25: =LN(T25) -> 10.846537 | AS25: =LN(U25) -> 10.758477 | AT25: =AR25*AS25 -> 116.69222 | AU25: =(AR25-AR$83)^2 -> 0.36278402 | AV25: =AR25^2 -> 117.64737 | AW25: =AS25^2 -> 115.74483
A26: 24 | B26: Красноярский край | C26: 47027 | D26: ='Показатели преступности России'!U27*1000 -> 51356 | O26: 24 | P26: Курганская область | Q26: 14765 | R26: ='Показатели преступности России'!D28 -> 26605 | T26: =R26 -> 26605 | U26: =Q26 -> 14765 | V26: =T26*U26 -> 392822825 | W26: =(T26-T$83)^2 -> 1.0533507e+08 | X26: =T26^2 -> 707826025 | Y26: =U26^2 -> 218005225 | AR26: =LN(T26) -> 10.188854 | AS26: =LN(U26) -> 9.6000148 | AT26: =AR26*AS26 -> 97.813153 | AU26: =(AR26-AR$83)^2 -> 0.0030655112 | AV26: =AR26^2 -> 103.81275 | AW26: =AS26^2 -> 92.160284
A27: 25 | B27: Курганская область | C27: 14765 | D27: ='Показатели преступности России'!U28*1000 -> 26605 | O27: 25 | P27: Курская область | Q27: 13538 | R27: ='Показатели преступности России'!D29 -> 22315 | T27: =R27 -> 22315 | U27: =Q27 -> 13538 | V27: =T27*U27 -> 302100470 | W27: =(T27-T$83)^2 -> 2.1179818e+08 | X27: =T27^2 -> 497959225 | Y27: =U27^2 -> 183277444 | AR27: =LN(T27) -> 10.013014 | AS27: =LN(U27) -> 9.5132558 | AT27: =AR27*AS27 -> 95.256367 | AU27: =(AR27-AR$83)^2 -> 0.053456736 | AV27: =AR27^2 -> 100.26046 | AW27: =AS27^2 -> 90.502036
A28: 26 | B28: Курская область | C28: 13538 | D28: ='Показатели преступности России'!U29*1000 -> 22315 | O28: 26 | P28: Ленинградская область | Q28: 27092 | R28: ='Показатели преступности России'!D30 -> 39681 | T28: =R28 -> 39681 | U28: =Q28 -> 27092 | V28: =T28*U28 -> 1075037652 | W28: =(T28-T$83)^2 -> 7911351.6 | X28: =T28^2 -> 1574581761 | Y28: =U28^2 -> 733976464 | AR28: =LN(T28) -> 10.588628 | AS28: =LN(U28) -> 10.206994 | AT28: =AR28*AS28 -> 108.07806 | AU28: =(AR28-AR$83)^2 -> 0.11861567 | AV28: =AR28^2 -> 112.11904 | AW28: =AS28^2 -> 104.18272
A29: 27 | B29: Ленинградская область | C29: 27092 | D29: ='Показатели преступности России'!U30*1000 -> 39681 | O29: 27 | P29: Липецкая область | Q29: 13073 | R29: ='Показатели преступности России'!D31 -> 26114 | T29: =R29 -> 26114 | U29: =Q29 -> 13073 | V29: =T29*U29 -> 341388322 | W29: =(T29-T$83)^2 -> 1.156547e+08 | X29: =T29^2 -> 681940996 | Y29: =U29^2 -> 170903329 | AR29: =LN(T29) -> 10.170227 | AS29: =LN(U29) -> 9.4783043 | AT29: =AR29*AS29 -> 96.396505 | AU29: =(AR29-AR$83)^2 -> 0.0054752093 | AV29: =AR29^2 -> 103.43351 | AW29: =AS29^2 -> 89.838253
A30: 28 | B30: Липецкая область | C30: 13073 | D30: ='Показатели преступности России'!U31*1000 -> 26114 | O30: 28 | P30: Магаданская область | Q30: 2562 | R30: ='Показатели преступности России'!D32 -> 4281 | T30: =R30 -> 4281 | U30: =Q30 -> 2562 | V30: =T30*U30 -> 10967922 | W30: =(T30-T$83)^2 -> 1.0619313e+09 | X30: =T30^2 -> 18326961 | Y30: =U30^2 -> 6563844 | AR30: =LN(T30) -> 8.3619419 | AS30: =LN(U30) -> 7.8485435 | AT30: =AR30*AS30 -> 65.629065 | AU30: =(AR30-AR$83)^2 -> 3.5429765 | AV30: =AR30^2 -> 69.922072 | AW30: =AS30^2 -> 61.599635
A31: 29 | B31: Магаданская область | C31: 2562 | D31: ='Показатели преступности России'!U32*1000 -> 4281 | O31: 29 | P31: Мурманская область | Q31: 12096 | R31: ='Показатели преступности России'!D34 -> 22113 | T31: =R31 -> 22113 | U31: =Q31 -> 12096 | V31: =T31*U31 -> 267478848 | W31: =(T31-T$83)^2 -> 2.1771851e+08 | X31: =T31^2 -> 488984769 | Y31: =U31^2 -> 146313216 | AR31: =LN(T31) -> 10.003921 | AS31: =LN(U31) -> 9.4006301 | AT31: =AR31*AS31 -> 94.04316 | AU31: =(AR31-AR$83)^2 -> 0.057744357 | AV31: =AR31^2 -> 100.07843 | AW31: =AS31^2 -> 88.371846
A32: 30 | B32: Московская область | C32: 73780 | D32: ='Показатели преступности России'!U33*1000 -> 154074 | O32: 30 | P32: Ненецкий АО | Q32: 852 | R32: ='Показатели преступности России'!D35 -> 1530 | T32: =R32 -> 1530 | U32: =Q32 -> 852 | V32: =T32*U32 -> 1303560 | W32: =(T32-T$83)^2 -> 1.2487946e+09 | X32: =T32^2 -> 2340900 | Y32: =U32^2 -> 725904 | AR32: =LN(T32) -> 7.333023 | AS32: =LN(U32) -> 6.7475865 | AT32: =AR32*AS32 -> 49.480207 | AU32: =(AR32-AR$83)^2 -> 8.4750767 | AV32: =AR32^2 -> 53.773227 | AW32: =AS32^2 -> 45.529924
A33: 31 | B33: Мурманская область | C33: 12096 | D33: ='Показатели преступности России'!U34*1000 -> 22113 | O33: 31 | P33: Нижегородская область | Q33: 40530 | R33: ='Показатели преступности России'!D36 -> 72297 | T33: =R33 -> 72297 | U33: =Q33 -> 40530 | V33: =T33*U33 -> 2930197410 | W33: =(T33-T$83)^2 -> 1.2551937e+09 | X33: =T33^2 -> 5226856209 | Y33: =U33^2 -> 1642680900 | AR33: =LN(T33) -> 11.188538 | AS33: =LN(U33) -> 10.609798 | AT33: =AR33*AS33 -> 118.70812 | AU33: =(AR33-AR$83)^2 -> 0.89173348 | AV33: =AR33^2 -> 125.18338 | AW33: =AS33^2 -> 112.56781
A34: 32 | B34: Ненецкий АО | C34: 852 | D34: ='Показатели преступности России'!U35*1000 -> 1530 | O34: 32 | P34: Новгородская область | Q34: 10630 | R34: ='Показатели преступности России'!D37 -> 12191 | T34: =R34 -> 12191 | U34: =Q34 -> 10630 | V34: =T34*U34 -> 129590330 | W34: =(T34-T$83)^2 -> 6.0896852e+08 | X34: =T34^2 -> 148620481 | Y34: =U34^2 -> 112996900 | AR34: =LN(T34) -> 9.4084533 | AS34: =LN(U34) -> 9.2714355 | AT34: =AR34*AS34 -> 87.229867 | AU34: =(AR34-AR$83)^2 -> 0.69850857 | AV34: =AR34^2 -> 88.518993 | AW34: =AS34^2 -> 85.959516
A35: 33 | B35: Нижегородская область | C35: 40530 | D35: ='Показатели преступности России'!U36*1000 -> 72297 | O35: 33 | P35: Новосибирская область | Q35: 46463 | R35: ='Показатели преступности России'!D38 -> 87071 | T35: =R35 -> 87071 | U35: =Q35 -> 46463 | V35: =T35*U35 -> 4045579873 | W35: =(T35-T$83)^2 -> 2.5203123e+09 | X35: =T35^2 -> 7581359041 | Y35: =U35^2 -> 2158810369 | AR35: =LN(T35) -> 11.374479 | AS35: =LN(U35) -> 10.746412 | AT35: =AR35*AS35 -> 122.23483 | AU35: =(AR35-AR$83)^2 -> 1.2774824 | AV35: =AR35^2 -> 129.37878 | AW35: =AS35^2 -> 115.48536
A36: 34 | B36: Новгородская область | C36: 10630 | D36: ='Показатели преступности России'!U37*1000 -> 12191 | O36: 34 | P36: Омская область | Q36: 23825 | R36: ='Показатели преступности России'!D39 -> 64125 | T36: =R36 -> 64125 | U36: =Q36 -> 23825 | V36: =T36*U36 -> 1527778125 | W36: =(T36-T$83)^2 -> 7.4292838e+08 | X36: =T36^2 -> 4112015625 | Y36: =U36^2 -> 567630625 | AR36: =LN(T36) -> 11.06859 | AS36: =LN(U36) -> 10.078491 | AT36: =AR36*AS36 -> 111.55468 | AU36: =(AR36-AR$83)^2 -> 0.67958273 | AV36: =AR36^2 -> 122.51368 | AW36: =AS36^2 -> 101.57598
A37: 35 | B37: Новосибирская область | C37: 46463 | D37: ='Показатели преступности России'!U38*1000 -> 87071 | O37: 35 | P37: Оренбургская область | Q37: 24989 | R37: ='Показатели преступности России'!D40 -> 43157 | T37: =R37 -> 43157 | U37: =Q37 -> 24989 | V37: =T37*U37 -> 1078450273 | W37: =(T37-T$83)^2 -> 39547905 | X37: =T37^2 -> 1862526649 | Y37: =U37^2 -> 624450121 | AR37: =LN(T37) -> 10.6726 | AS37: =LN(U37) -> 10.126191 | AT37: =AR37*AS37 -> 108.07279 | AU37: =(AR37-AR$83)^2 -> 0.18350806 | AV37: =AR37^2 -> 113.90439 | AW37: =AS37^2 -> 102.53974
A38: 36 | B38: Омская область | C38: 23825 | D38: ='Показатели преступности России'!U39*1000 -> 64125 | O38: 36 | P38: Орловская область | Q38: 8151 | R38: ='Показатели преступности России'!D41 -> 16337 | T38: =R38 -> 16337 | U38: =Q38 -> 8151 | V38: =T38*U38 -> 133162887 | W38: =(T38-T$83)^2 -> 4.2153377e+08 | X38: =T38^2 -> 266897569 | Y38: =U38^2 -> 66438801 | AR38: =LN(T38) -> 9.7011878 | AS38: =LN(U38) -> 9.0058959 | AT38: =AR38*AS38 -> 87.367887 | AU38: =(AR38-AR$83)^2 -> 0.29488566 | AV38: =AR38^2 -> 94.113044 | AW38: =AS38^2 -> 81.106161
A39: 37 | B39: Оренбургская область | C39: 24989 | D39: ='Показатели преступности России'!U40*1000 -> 43157 | O39: 37 | P39: Пензенская область | Q39: 13470 | R39: ='Показатели преступности России'!D42 -> 27941 | T39: =R39 -> 27941 | U39: =Q39 -> 13470 | V39: =T39*U39 -> 376365270 | W39: =(T39-T$83)^2 -> 79696462 | X39: =T39^2 -> 780699481 | Y39: =U39^2 -> 181440900 | AR39: =LN(T39) -> 10.23785 | AS39: =LN(U39) -> 9.5082203 | AT39: =AR39*AS39 -> 97.343737 | AU39: =(AR39-AR$83)^2 -> 4.059069e-05 | AV39: =AR39^2 -> 104.81358 | AW39: =AS39^2 -> 90.406253
A40: 38 | B40: Орловская область | C40: 8151 | D40: ='Показатели преступности России'!U41*1000 -> 16337 | O40: 38 | P40: Пермский край | Q40: 40594 | R40: ='Показатели преступности России'!D43 -> 56349 | T40: =R40 -> 56349 | U40: =Q40 -> 40594 | V40: =T40*U40 -> 2287431306 | W40: =(T40-T$83)^2 -> 3.7949816e+08 | X40: =T40^2 -> 3175209801 | Y40: =U40^2 -> 1647872836 | AR40: =LN(T40) -> 10.93932 | AS40: =LN(U40) -> 10.611376 | AT40: =AR40*AS40 -> 116.08123 | AU40: =(AR40-AR$83)^2 -> 0.4831616 | AV40: =AR40^2 -> 119.66872 | AW40: =AS40^2 -> 112.60129
...
